Workbook
Name CL_C_CASFIM: CAT_C_CASFIM!$A$2:$A$40278
Name CL_C_GARANT_ANEXO_A: CAT_C_GARANT_ANEXO_A!$A$2:$A$4
Name CL_C_GARANT_ANEXO_AD: CAT_C_GARANT_ANEXO_AD!$A$2:$A$47
Name CL_C_GARANT_ANEXO_AF: CAT_C_GARANT_ANEXO_AF!$A$2:$A$8169
Name CL_C_GARANT_ANEXO_E: CAT_C_GARANT_ANEXO_E!$A$2:$A$54

Sheet VALIDACION
A1: RESUMEN DE VALIDACIÓN
A2: Total celdas con error de formato: | C2: =SUM(CHK!A2:N201) -> 26
A3: Estado: | C3: =IF(C2=0,"✔ SIN ERRORES DE FORMATO","✖ REVISAR: "&C2&" celda(s) marcada(s) en rojo") -> ✖ REVISAR: 26 celda(s) marcada(s) en rojo
A5: Orden | B5: Campo | C5: Tipo | D5: Long | E5: Catálogo | F5: # Errores | G5: # Vacíos (obligatorio)
A6: 1 | B6: OFICINA | C6: TEXTO | D6: 1 | E6: C_GARANT_ANEXO_A | F6: =SUM(CHK!A2:A201) -> 8 | G6: =COUNTBLANK(GARANTIAS_II!A2:A201) -> 190
A7: 2 | B7: CONT | C7: TEXTO | D7: 6 | E7: C_CASFIM | F7: =SUM(CHK!B2:B201) -> 10 | G7: =COUNTBLANK(GARANTIAS_II!B2:B201) -> 190
A8: 3 | B8: ID_GAR | C8: TEXTO | D8: 20 | E8: — | F8: =SUM(CHK!C2:C201) -> 0 | G8: =COUNTBLANK(GARANTIAS_II!C2:C201) -> 190
A9: 4 | B9: CON_GTA | C9: NUMERICO | D9: 3 | E9: — | F9: =SUM(CHK!D2:D201) -> 0 | G9: =COUNTBLANK(GARANTIAS_II!D2:D201) -> 190
A10: 5 | B10: POS_GTA | C10: TEXTO | D10: 1 | E10: — | F10: =SUM(CHK!E2:E201) -> 0 | G10: =COUNTBLANK(GARANTIAS_II!E2:E201) -> 190
A11: 6 | B11: TIP_GTA | C11: NUMERICO | D11: 2 | E11: C_GARANT_ANEXO_AD | F11: =SUM(CHK!F2:F201) -> 0 | G11: =COUNTBLANK(GARANTIAS_II!F2:F201) -> 190
A12: 7 | B12: CVE_TIT | C12: TEXTO | D12: 20 | E12: C_GARANT_ANEXO_AF | F12: =SUM(CHK!G2:G201) -> 8 | G12: =COUNTBLANK(GARANTIAS_II!G2:G201) -> 190
A13: 8 | B13: EMI_ACT | C13: TEXTO | D13: 6 | E13: — | F13: =SUM(CHK!H2:H201) -> 0 | G13: =COUNTBLANK(GARANTIAS_II!H2:H201) -> 190
A14: 9 | B14: FE_AV_BI | C14: FECHA | D14: YYYY-MM-DD | E14: — | F14: =SUM(CHK!I2:I201) -> 0 | G14: =COUNTBLANK(GARANTIAS_II!I2:I201) -> 190
A15: 10 | B15: RE_BM_BI | C15: TEXTO | D15: 20 | E15: — | F15: =SUM(CHK!J2:J201) -> 0 | G15: =COUNTBLANK(GARANTIAS_II!J2:J201) -> 190
A16: 11 | B16: AFORO | C16: NUMERICO | D16: 5,2 | E16: — | F16: =SUM(CHK!K2:K201) -> 0 | G16: =COUNTBLANK(GARANTIAS_II!K2:K201) -> 190
A17: 12 | B17: VAL_GTA | C17: NUMERICO | D17: 15 | E17: — | F17: =SUM(CHK!L2:L201) -> 0 | G17: =COUNTBLANK(GARANTIAS_II!L2:L201) -> 190
A18: 13 | B18: MDA_GTA | C18: NUMERICO | D18: 3 | E18: C_GARANT_ANEXO_E | F18: =SUM(CHK!M2:M201) -> 0 | G18: =COUNTBLANK(GARANTIAS_II!M2:M201) -> 190
A19: 14 | B19: FECHAINFO | C19: FECHA | D19: DD/MM/AAAA | E19: — | F19: =SUM(CHK!N2:N201) -> 0 | G19: =COUNTBLANK(GARANTIAS_II!N2:N201) -> 190

Sheet GARANTIAS_II
A1: OFICINA | B1: CONT | C1: ID_GAR | D1: CON_GTA | E1: POS_GTA | F1: TIP_GTA | G1: CVE_TIT | H1: EMI_ACT | I1: FE_AV_BI | J1: RE_BM_BI | K1: AFORO | L1: VAL_GTA | M1: MDA_GTA | N1: FECHAINFO
A2: C | B2: 2 | C2: GAR00000000000000002 | D2: 2 | E2: E | F2: 3 | G2: MNX | H2: 2 | I2: 46129 | J2: NR | K2: 95 | L2: 1000 | M2: 978 | N2: 46189
A3: B | B3: 6 | C3: GAR00000000000000006 | D3: 6 | E3: E | F3: 2 | G3: ARSMXN | H3: 2 | I3: 46009 | J3: NR | K3: 85 | L3: 3000 | M3: 484 | N3: 46189
A4: E | B4: 4 | C4: GAR00000000000000004 | D4: 4 | E4: E | F4: 5 | G4: BONDES | H4: NA | I4: 46069 | J4: NR | K4: 90 | L4: 2000 | M4: 840 | N4: 46189
A5: B | B5: 1 | C5: GAR00000000000000001 | D5: 1 | E5: R | F5: 17 | G5: MXN | H5: 1 | I5: 46159 | J5: NA | K5: 97.5 | L5: 500 | M5: 840 | N5: 46189
A6: C | B6: 7 | C6: GAR00000000000000007 | D6: 7 | E6: R | F6: 3 | G6: NA | H6: 3 | I6: 45979 | J6: NA | K6: 82.5 | L6: 3500 | M6: 840 | N6: 46189
A7: A | B7: 10 | C7: GAR00000000000000010 | D7: 10 | E7: E | F7: 1 | G7: BNDM | H7: 2 | I7: 45889 | J7: NR | K7: 75 | L7: 5000 | M7: 840 | N7: 46189
A8: D | B8: 8 | C8: GAR00000000000000008 | D8: 8 | E8: E | F8: 4 | G8: CETES | H8: NA | I8: 45949 | J8: NR | K8: 80 | L8: 4000 | M8: 978 | N8: 46189
A9: A | B9: 5 | C9: GAR00000000000000005 | D9: 5 | E9: R | F9: 1 | G9: BNDM | H9: 1 | I9: 46039 | J9: NA | K9: 87.5 | L9: 2500 | M9: 978 | N9: 46189
A10: D | B10: 3 | C10: GAR00000000000000003 | D10: 3 | E10: R | F10: 4 | G10: CETES | H10: 3 | I10: 46099 | J10: NA | K10: 92.5 | L10: 1500 | M10: 484 | N10: 46189
A11: E | B11: 9 | C11: GAR00000000000000009 | D11: 9 | E11: R | F11: 5 | G11: BONDES | H11: 1 | I11: 45919 | J11: NA | K11: 77.5 | L11: 4500 | M11: 484 | N11: 46189

Sheet CAT_C_CASFIM
A1: Clave | B1: Descripcion
A2: 000111 | B2: AGENTE DE CALCULO Y/O LIQUIDADOR
A3: 000434
A4: 000750 | B4: OTROS INTERMEDIARIOS FINANCIEROS MEXICANOS
A5: 000760 | B5: GOBIERNO FEDERAL EXCEPTO LA SHCP
A6: 000770 | B6: GOBIERNOS DE LOS ESTADOS (EXCLUYENDO AL DEL D.F.) Y DE LOS MUNICIPIOS.
A7: 000775 | B7: GOBIERNO DEL DISTRITO FEDERAL
A8: 000780 | B8: FONDOS DE RESERVA PARA PENSIONES JUBILACIONES Y DEMAS PRESTACIONES DEL PERSONAL DE LA PROPIA INSTITUCION
A9: 000790 | B9: ARREND FACTORAJES CASAS CAMBIO SOFOLES Y AFIANZADORAS DEL GRUPO FINANCIERO AL QUE PERTENECE LA INSTITUCION O FILIALES FINANCIERAS DE LA INSTITUCION
A10: 000791 | B10: ARRENDADORAS FINANCIERAS PRIVADAS DEL GRUPO FINANCIERO AL QUE PERTENECE LA INSTITUCION O FILIALES FINANCIERAS DE LA INSTITUCION
A11: 000792 | B11: EMPRESAS DE FACTORAJE DEL GRUPO FINANCIERO AL QUE PERTENECE LA INSTITUCION O FILIALES FINANCIERAS DE LA INSTITUCION
A12: 000793 | B12: CASAS DE CAMBIO DEL GRUPO FINANCIERO AL QUE PERTENECE LA INSTITUCION O FILIALES FINANCIERAS DE LA INSTITUCION
A13: 000794 | B13: SOFOLES DEL GRUPO FINANCIERO AL QUE PERTENECE LA INSTITUCION O FILIALES FINANCIERAS DE LA INSTITUCION
A14: 000795 | B14: AFIANZADORAS DEL GRUPO FINANCIERO AL QUE PERTENECE LA INSTITUCION O FILIALES FINANCIERAS DE LA INSTITUCION
A15: 000800 | B15: ARRED FACTORAJES CASAS CAMBIO SOFOLES AFIANZADORAS QUE NO FORMEN PARTE DEL GPO FINANC AL QUE PERTENECE LA INST O NO SEAN FILIALES DE LA INSTITUCION
... A36: 002001 | B36: BANCO DE MEXICO (BANXICO)
A37: 002300
A38: 001230
A39: 001328
A40: 001382
A41: 001579
A42: 004516 | B42: AFORE XXI
A43: 004530 | B43: BANORTE GENERALI SA DE CV AFORE
A44: 004532 | B44: HSBC AFORE GRUPO FINANCIERO HSBC
A45: 004534 | B45: PROFUTURO GNP SA DE CV AFORE
A46: 004538 | B46: PRINCIPAL AFORE
A47: 004540 | B47: SANTANDER MEXICANO SA DE CV AFORE
A48: 004544 | B48: AFORE SURA SA DE CV
A49: 004548 | B49: GARANTE SA DE CV AFORE
A50: 004550 | B50: AFORE INBURSA
A51: 004552 | B51: AFORE BANAMEX SA DE CV
A52: 004554 | B52: ADMINISTRADORA DE FONDOS PARA EL RETIRO BANCOMER SA DE CV
A53: 004556 | B53: AFORE AZTECA
... A85: 003100 | B85: FV MEXSOLAR II, S.A.P.I. DE C.V.
A86: 002301
A87: 002546
A88: 010002 | B88: ARRENDADORA GBM ATLANTICO SA DE CV
A89: 010007 | B89: ARRENDADORA ATLAS
A90: 010010 | B90: ARRENDADORA VALMEX
A91: 010014 | B91: ARRENDADORA VE POR MAS
...

Sheet CAT_C_GARANT_ANEXO_A
A1: Clave | B1: Descripcion
A2: A | B2: La operación fue concertada por alguna de las Agencias o Sucursales en el Extranjero (fuera de la República Mexicana), de la Institución.
A3: F | B3: La operación fue concertada por alguna de las Entidades Financieras Filiales en el Extranjero (fuera de la República Mexicana), de la Institución.
A4: R | B4: La operación fue concertada por la oficina matriz, o por otras oficinas de la Institución, dentro de la República Mexicana.

Sheet CAT_C_GARANT_ANEXO_AD
A1: Clave | B1: Descripcion
A2: 1 | B2: Depósito bancario (vista y/o plazo) en moneda nacional en la propia institución (o en el banco múltiple del mismo grupo financiero).
A3: 10 | B3: Títulos de deuda bursátiles emitidos o avalados por alguna institución bancaria residente en México, denominados en moneda nacional, con una calificación igual o mayor a grado de inversión.
A4: 11 | B4: Títulos de deuda bursátiles emitidos o avalados por alguna institución bancaria residente en México, denominados en moneda extranjera, con una calificación igual o mayor a grado de inversión.
A5: 12 | B5: Títulos de deuda bursátiles emitidos o avalados por alguna institución bancaria residente en México, denominados en moneda nacional, con una calificación inferior al grado de inversión.
A6: 13 | B6: Títulos de deuda bursátiles emitidos o avalados por alguna institución bancaria residente en México, denominados en moneda extranjera, con una calificación inferior al grado de inversión.
A7: 14 | B7: Títulos de deuda bursátiles emitidos o avalados por alguna institución bancaria residente en el extranjero, con una calificación igual o mayor a grado de inversión.
A8: 2 | B8: Depósito bancario (vista y/o plazo) en moneda extranjera en la propia institución (o en el banco múltiple del mismo grupo financiero)
A9: 15 | B9: Títulos de deuda bursátiles emitidos o avalados por alguna institución bancaria residente en el extranjero, con una calificación inferior al grado de inversión.
A10: 16 | B10: Títulos de deuda bursátiles emitidos o avalados por alguna entidad no bancaria residente en México, denominados en moneda nacional, con una calificación igual o mayor a grado de inversión.
A11: 17 | B11: Títulos de deuda bursátiles emitidos o avalados por alguna entidad no bancaria residente en México, denominados en moneda extranjera, con una calificación igual o mayor a grado de inversión.
A12: 18 | B12: Títulos de deuda bursátiles emitidos o avalados por alguna entidad no bancaria residente en México, denominados en moneda nacional, con una calificación inferior al grado de inversión.
... A47: 9 | B47: Títulos de deuda bursátiles emitidos o avalados por el gobierno central de algún país extranjero (incluye el banco central respectivo), con una calificación inferior al grado de inversión.

Sheet CAT_C_GARANT_ANEXO_AF
A1: Clave | B1: Descripcion
A2: AEDUSD | B2: DIRHAM DE LOS EMIRATOS ÁRABES UNIDOS LIQUIDABLE CON DÓLAR DE LOS EE.UU.A.
A3: AN8068571086 | B3: SCHLUMBERGER LTD
A4: ARSMXN | B4: PESOS ARGENTINOS LIQUIDABLE CON PESO MEXICANO
A5: AT0000383864 | B5: BONOS DE LOS GOBIERNOS EMITIDOS EXT.
A6: AT0000A04967 | B6: EUR 4,15 AUSTRIA, REP.OF 07-2037
A7: AT0000A0DXC2 | B7: EUR 4,85 AUSTRIA, REP.OF (REGS) 09-2026
A8: AT0000A0N9A0 | B8: EUR 3,65 AUSTRIA, REP.OF 11-2022
A9: AT0000A0VRQ6 | B9: BONOS DE LOS GOBIERNOS EMITIDOS EXT.
A10: AT0000A105W3 | B10: EUR 1,75 AUSTRIA, REP.OF (REGS) 13-2023
A11: AT0000A185T1 | B11: EUR 1,65 AUSTRIA, REP.OF 14-2024
A12: AT0000A1K9C8 | B12: EUR 0,75 AUSTRIA, REP.OF 16-2026
... A8169: ZS | B8169: FUTURO SOBRE LA SOYA

Sheet CAT_C_GARANT_ANEXO_E
A1: Clave | B1: Descripcion
A2: 0 | B2: No aplica
A3: 102 | B3: Salario Mínimo Diario Vigente en el Distrito Federal (zona A)
A4: 124 | B4: Dólar Canadiense
A5: 152 | B5: Peso Chileno
A6: 156 | B6: Yuan Chino
A7: 157 | B7: Yuan Chino Extracontinental
A8: 32 | B8: Pesos Argentinos
A9: 36 | B9: Dólar Australiano
A10: 170 | B10: Peso Colombiano
A11: 203 | B11: Corona Checa
A12: 208 | B12: Corona Danesa
... A54: 990 | B54: Unidades de Fomento Chilenas

Sheet CHK
A2: =IF(AND(GARANTIAS_II!A2<>"",OR(LEN(GARANTIAS_II!A2)>1,COUNTIF(CL_C_GARANT_ANEXO_A,GARANTIAS_II!A2)=0)),1,0) -> 1 | B2: =IF(AND(GARANTIAS_II!B2<>"",OR(LEN(GARANTIAS_II!B2)>6,COUNTIF(CL_C_CASFIM,GARANTIAS_II!B2)=0)),1,0) -> 1 | C2: =IF(AND(GARANTIAS_II!C2<>"",LEN(GARANTIAS_II!C2)>20),1,0) -> 0 | D2: =IF(AND(GARANTIAS_II!D2<>"",IF(ISNUMBER(GARANTIAS_II!D2),OR(GARANTIAS_II!D2<>INT(GARANTIAS_II!D2),LEN(TEXT(ABS(GARANTIAS_II!D2),"0"))>3),TRUE)),1,0) -> 0 | E2: =IF(AND(GARANTIAS_II!E2<>"",LEN(GARANTIAS_II!E2)>1),1,0) -> 0 | F2: =IF(AND(GARANTIAS_II!F2<>"",COUNTIF(CL_C_GARANT_ANEXO_AD,GARANTIAS_II!F2)=0),1,0) -> 0 | G2: =IF(AND(GARANTIAS_II!G2<>"",OR(LEN(GARANTIAS_II!G2)>20,COUNTIF(CL_C_GARANT_ANEXO_AF,GARANTIAS_II!G2)=0)),1,0) -> 0 | H2: =IF(AND(GARANTIAS_II!H2<>"",LEN(GARANTIAS_II!H2)>6),1,0) -> 0 | I2: =IF(AND(GARANTIAS_II!I2<>"",NOT(ISNUMBER(GARANTIAS_II!I2))),1,0) -> 0 | J2: =IF(AND(GARANTIAS_II!J2<>"",LEN(GARANTIAS_II!J2)>20),1,0) -> 0 | K2: =IF(AND(GARANTIAS_II!K2<>"",IF(ISNUMBER(GARANTIAS_II!K2),OR(GARANTIAS_II!K2<>ROUND(GARANTIAS_II!K2,2),LEN(TEXT(INT(ABS(GARANTIAS_II!K2)),"0"))>5),TRUE)),1,0) -> 0 | L2: =IF(AND(GARANTIAS_II!L2<>"",IF(ISNUMBER(GARANTIAS_II!L2),OR(GARANTIAS_II!L2<>INT(GARANTIAS_II!L2),LEN(TEXT(ABS(GARANTIAS_II!L2),"0"))>15),TRUE)),1,0) -> 0 | M2: =IF(AND(GARANTIAS_II!M2<>"",COUNTIF(CL_C_GARANT_ANEXO_E,GARANTIAS_II!M2)=0),1,0) -> 0 | N2: =IF(AND(GARANTIAS_II!N2<>"",NOT(ISNUMBER(GARANTIAS_II!N2))),1,0) -> 0
A3: =IF(AND(GARANTIAS_II!A3<>"",OR(LEN(GARANTIAS_II!A3)>1,COUNTIF(CL_C_GARANT_ANEXO_A,GARANTIAS_II!A3)=0)),1,0) -> 1 | B3: =IF(AND(GARANTIAS_II!B3<>"",OR(LEN(GARANTIAS_II!B3)>6,COUNTIF(CL_C_CASFIM,GARANTIAS_II!B3)=0)),1,0) -> 1 | C3: =IF(AND(GARANTIAS_II!C3<>"",LEN(GARANTIAS_II!C3)>20),1,0) -> 0 | D3: =IF(AND(GARANTIAS_II!D3<>"",IF(ISNUMBER(GARANTIAS_II!D3),OR(GARANTIAS_II!D3<>INT(GARANTIAS_II!D3),LEN(TEXT(ABS(GARANTIAS_II!D3),"0"))>3),TRUE)),1,0) -> 0 | E3: =IF(AND(GARANTIAS_II!E3<>"",LEN(GARANTIAS_II!E3)>1),1,0) -> 0 | F3: =IF(AND(GARANTIAS_II!F3<>"",COUNTIF(CL_C_GARANT_ANEXO_AD,GARANTIAS_II!F3)=0),1,0) -> 0 | G3: =IF(AND(GARANTIAS_II!G3<>"",OR(LEN(GARANTIAS_II!G3)>20,COUNTIF(CL_C_GARANT_ANEXO_AF,GARANTIAS_II!G3)=0)),1,0) -> 0 | H3: =IF(AND(GARANTIAS_II!H3<>"",LEN(GARANTIAS_II!H3)>6),1,0) -> 0 | I3: =IF(AND(GARANTIAS_II!I3<>"",NOT(ISNUMBER(GARANTIAS_II!I3))),1,0) -> 0 | J3: =IF(AND(GARANTIAS_II!J3<>"",LEN(GARANTIAS_II!J3)>20),1,0) -> 0 | K3: =IF(AND(GARANTIAS_II!K3<>"",IF(ISNUMBER(GARANTIAS_II!K3),OR(GARANTIAS_II!K3<>ROUND(GARANTIAS_II!K3,2),LEN(TEXT(INT(ABS(GARANTIAS_II!K3)),"0"))>5),TRUE)),1,0) -> 0 | L3: =IF(AND(GARANTIAS_II!L3<>"",IF(ISNUMBER(GARANTIAS_II!L3),OR(GARANTIAS_II!L3<>INT(GARANTIAS_II!L3),LEN(TEXT(ABS(GARANTIAS_II!L3),"0"))>15),TRUE)),1,0) -> 0 | M3: =IF(AND(GARANTIAS_II!M3<>"",COUNTIF(CL_C_GARANT_ANEXO_E,GARANTIAS_II!M3)=0),1,0) -> 0 | N3: =IF(AND(GARANTIAS_II!N3<>"",NOT(ISNUMBER(GARANTIAS_II!N3))),1,0) -> 0
A4: =IF(AND(GARANTIAS_II!A4<>"",OR(LEN(GARANTIAS_II!A4)>1,COUNTIF(CL_C_GARANT_ANEXO_A,GARANTIAS_II!A4)=0)),1,0) -> 1 | B4: =IF(AND(GARANTIAS_II!B4<>"",OR(LEN(GARANTIAS_II!B4)>6,COUNTIF(CL_C_CASFIM,GARANTIAS_II!B4)=0)),1,0) -> 1 | C4: =IF(AND(GARANTIAS_II!C4<>"",LEN(GARANTIAS_II!C4)>20),1,0) -> 0 | D4: =IF(AND(GARANTIAS_II!D4<>"",IF(ISNUMBER(GARANTIAS_II!D4),OR(GARANTIAS_II!D4<>INT(GARANTIAS_II!D4),LEN(TEXT(ABS(GARANTIAS_II!D4),"0"))>3),TRUE)),1,0) -> 0 | E4: =IF(AND(GARANTIAS_II!E4<>"",LEN(GARANTIAS_II!E4)>1),1,0) -> 0 | F4: =IF(AND(GARANTIAS_II!F4<>"",COUNTIF(CL_C_GARANT_ANEXO_AD,GARANTIAS_II!F4)=0),1,0) -> 0 | G4: =IF(AND(GARANTIAS_II!G4<>"",OR(LEN(GARANTIAS_II!G4)>20,COUNTIF(CL_C_GARANT_ANEXO_AF,GARANTIAS_II!G4)=0)),1,0) -> 1 | H4: =IF(AND(GARANTIAS_II!H4<>"",LEN(GARANTIAS_II!H4)>6),1,0) -> 0 | I4: =IF(AND(GARANTIAS_II!I4<>"",NOT(ISNUMBER(GARANTIAS_II!I4))),1,0) -> 0 | J4: =IF(AND(GARANTIAS_II!J4<>"",LEN(GARANTIAS_II!J4)>20),1,0) -> 0 | K4: =IF(AND(GARANTIAS_II!K4<>"",IF(ISNUMBER(GARANTIAS_II!K4),OR(GARANTIAS_II!K4<>ROUND(GARANTIAS_II!K4,2),LEN(TEXT(INT(ABS(GARANTIAS_II!K4)),"0"))>5),TRUE)),1,0) -> 0 | L4: =IF(AND(GARANTIAS_II!L4<>"",IF(ISNUMBER(GARANTIAS_II!L4),OR(GARANTIAS_II!L4<>INT(GARANTIAS_II!L4),LEN(TEXT(ABS(GARANTIAS_II!L4),"0"))>15),TRUE)),1,0) -> 0 | M4: =IF(AND(GARANTIAS_II!M4<>"",COUNTIF(CL_C_GARANT_ANEXO_E,GARANTIAS_II!M4)=0),1,0) -> 0 | N4: =IF(AND(GARANTIAS_II!N4<>"",NOT(ISNUMBER(GARANTIAS_II!N4))),1,0) -> 0
A5: =IF(AND(GARANTIAS_II!A5<>"",OR(LEN(GARANTIAS_II!A5)>1,COUNTIF(CL_C_GARANT_ANEXO_A,GARANTIAS_II!A5)=0)),1,0) -> 1 | B5: =IF(AND(GARANTIAS_II!B5<>"",OR(LEN(GARANTIAS_II!B5)>6,COUNTIF(CL_C_CASFIM,GARANTIAS_II!B5)=0)),1,0) -> 1 | C5: =IF(AND(GARANTIAS_II!C5<>"",LEN(GARANTIAS_II!C5)>20),1,0) -> 0 | D5: =IF(AND(GARANTIAS_II!D5<>"",IF(ISNUMBER(GARANTIAS_II!D5),OR(GARANTIAS_II!D5<>INT(GARANTIAS_II!D5),LEN(TEXT(ABS(GARANTIAS_II!D5),"0"))>3),TRUE)),1,0) -> 0 | E5: =IF(AND(GARANTIAS_II!E5<>"",LEN(GARANTIAS_II!E5)>1),1,0) -> 0 | F5: =IF(AND(GARANTIAS_II!F5<>"",COUNTIF(CL_C_GARANT_ANEXO_AD,GARANTIAS_II!F5)=0),1,0) -> 0 | G5: =IF(AND(GARANTIAS_II!G5<>"",OR(LEN(GARANTIAS_II!G5)>20,COUNTIF(CL_C_GARANT_ANEXO_AF,GARANTIAS_II!G5)=0)),1,0) -> 1 | H5: =IF(AND(GARANTIAS_II!H5<>"",LEN(GARANTIAS_II!H5)>6),1,0) -> 0 | I5: =IF(AND(GARANTIAS_II!I5<>"",NOT(ISNUMBER(GARANTIAS_II!I5))),1,0) -> 0 | J5: =IF(AND(GARANTIAS_II!J5<>"",LEN(GARANTIAS_II!J5)>20),1,0) -> 0 | K5: =IF(AND(GARANTIAS_II!K5<>"",IF(ISNUMBER(GARANTIAS_II!K5),OR(GARANTIAS_II!K5<>ROUND(GARANTIAS_II!K5,2),LEN(TEXT(INT(ABS(GARANTIAS_II!K5)),"0"))>5),TRUE)),1,0) -> 0 | L5: =IF(AND(GARANTIAS_II!L5<>"",IF(ISNUMBER(GARANTIAS_II!L5),OR(GARANTIAS_II!L5<>INT(GARANTIAS_II!L5),LEN(TEXT(ABS(GARANTIAS_II!L5),"0"))>15),TRUE)),1,0) -> 0 | M5: =IF(AND(GARANTIAS_II!M5<>"",COUNTIF(CL_C_GARANT_ANEXO_E,GARANTIAS_II!M5)=0),1,0) -> 0 | N5: =IF(AND(GARANTIAS_II!N5<>"",NOT(ISNUMBER(GARANTIAS_II!N5))),1,0) -> 0
A6: =IF(AND(GARANTIAS_II!A6<>"",OR(LEN(GARANTIAS_II!A6)>1,COUNTIF(CL_C_GARANT_ANEXO_A,GARANTIAS_II!A6)=0)),1,0) -> 1 | B6: =IF(AND(GARANTIAS_II!B6<>"",OR(LEN(GARANTIAS_II!B6)>6,COUNTIF(CL_C_CASFIM,GARANTIAS_II!B6)=0)),1,0) -> 1 | C6: =IF(AND(GARANTIAS_II!C6<>"",LEN(GARANTIAS_II!C6)>20),1,0) -> 0 | D6: =IF(AND(GARANTIAS_II!D6<>"",IF(ISNUMBER(GARANTIAS_II!D6),OR(GARANTIAS_II!D6<>INT(GARANTIAS_II!D6),LEN(TEXT(ABS(GARANTIAS_II!D6),"0"))>3),TRUE)),1,0) -> 0 | E6: =IF(AND(GARANTIAS_II!E6<>"",LEN(GARANTIAS_II!E6)>1),1,0) -> 0 | F6: =IF(AND(GARANTIAS_II!F6<>"",COUNTIF(CL_C_GARANT_ANEXO_AD,GARANTIAS_II!F6)=0),1,0) -> 0 | G6: =IF(AND(GARANTIAS_II!G6<>"",OR(LEN(GARANTIAS_II!G6)>20,COUNTIF(CL_C_GARANT_ANEXO_AF,GARANTIAS_II!G6)=0)),1,0) -> 1 | H6: =IF(AND(GARANTIAS_II!H6<>"",LEN(GARANTIAS_II!H6)>6),1,0) -> 0 | I6: =IF(AND(GARANTIAS_II!I6<>"",NOT(ISNUMBER(GARANTIAS_II!I6))),1,0) -> 0 | J6: =IF(AND(GARANTIAS_II!J6<>"",LEN(GARANTIAS_II!J6)>20),1,0) -> 0 | K6: =IF(AND(GARANTIAS_II!K6<>"",IF(ISNUMBER(GARANTIAS_II!K6),OR(GARANTIAS_II!K6<>ROUND(GARANTIAS_II!K6,2),LEN(TEXT(INT(ABS(GARANTIAS_II!K6)),"0"))>5),TRUE)),1,0) -> 0 | L6: =IF(AND(GARANTIAS_II!L6<>"",IF(ISNUMBER(GARANTIAS_II!L6),OR(GARANTIAS_II!L6<>INT(GARANTIAS_II!L6),LEN(TEXT(ABS(GARANTIAS_II!L6),"0"))>15),TRUE)),1,0) -> 0 | M6: =IF(AND(GARANTIAS_II!M6<>"",COUNTIF(CL_C_GARANT_ANEXO_E,GARANTIAS_II!M6)=0),1,0) -> 0 | N6: =IF(AND(GARANTIAS_II!N6<>"",NOT(ISNUMBER(GARANTIAS_II!N6))),1,0) -> 0
A7: =IF(AND(GARANTIAS_II!A7<>"",OR(LEN(GARANTIAS_II!A7)>1,COUNTIF(CL_C_GARANT_ANEXO_A,GARANTIAS_II!A7)=0)),1,0) -> 0 | B7: =IF(AND(GARANTIAS_II!B7<>"",OR(LEN(GARANTIAS_II!B7)>6,COUNTIF(CL_C_CASFIM,GARANTIAS_II!B7)=0)),1,0) -> 1 | C7: =IF(AND(GARANTIAS_II!C7<>"",LEN(GARANTIAS_II!C7)>20),1,0) -> 0 | D7: =IF(AND(GARANTIAS_II!D7<>"",IF(ISNUMBER(GARANTIAS_II!D7),OR(GARANTIAS_II!D7<>INT(GARANTIAS_II!D7),LEN(TEXT(ABS(GARANTIAS_II!D7),"0"))>3),TRUE)),1,0) -> 0 | E7: =IF(AND(GARANTIAS_II!E7<>"",LEN(GARANTIAS_II!E7)>1),1,0) -> 0 | F7: =IF(AND(GARANTIAS_II!F7<>"",COUNTIF(CL_C_GARANT_ANEXO_AD,GARANTIAS_II!F7)=0),1,0) -> 0 | G7: =IF(AND(GARANTIAS_II!G7<>"",OR(LEN(GARANTIAS_II!G7)>20,COUNTIF(CL_C_GARANT_ANEXO_AF,GARANTIAS_II!G7)=0)),1,0) -> 1 | H7: =IF(AND(GARANTIAS_II!H7<>"",LEN(GARANTIAS_II!H7)>6),1,0) -> 0 | I7: =IF(AND(GARANTIAS_II!I7<>"",NOT(ISNUMBER(GARANTIAS_II!I7))),1,0) -> 0 | J7: =IF(AND(GARANTIAS_II!J7<>"",LEN(GARANTIAS_II!J7)>20),1,0) -> 0 | K7: =IF(AND(GARANTIAS_II!K7<>"",IF(ISNUMBER(GARANTIAS_II!K7),OR(GARANTIAS_II!K7<>ROUND(GARANTIAS_II!K7,2),LEN(TEXT(INT(ABS(GARANTIAS_II!K7)),"0"))>5),TRUE)),1,0) -> 0 | L7: =IF(AND(GARANTIAS_II!L7<>"",IF(ISNUMBER(GARANTIAS_II!L7),OR(GARANTIAS_II!L7<>INT(GARANTIAS_II!L7),LEN(TEXT(ABS(GARANTIAS_II!L7),"0"))>15),TRUE)),1,0) -> 0 | M7: =IF(AND(GARANTIAS_II!M7<>"",COUNTIF(CL_C_GARANT_ANEXO_E,GARANTIAS_II!M7)=0),1,0) -> 0 | N7: =IF(AND(GARANTIAS_II!N7<>"",NOT(ISNUMBER(GARANTIAS_II!N7))),1,0) -> 0
A8: =IF(AND(GARANTIAS_II!A8<>"",OR(LEN(GARANTIAS_II!A8)>1,COUNTIF(CL_C_GARANT_ANEXO_A,GARANTIAS_II!A8)=0)),1,0) -> 1 | B8: =IF(AND(GARANTIAS_II!B8<>"",OR(LEN(GARANTIAS_II!B8)>6,COUNTIF(CL_C_CASFIM,GARANTIAS_II!B8)=0)),1,0) -> 1 | C8: =IF(AND(GARANTIAS_II!C8<>"",LEN(GARANTIAS_II!C8)>20),1,0) -> 0 | D8: =IF(AND(GARANTIAS_II!D8<>"",IF(ISNUMBER(GARANTIAS_II!D8),OR(GARANTIAS_II!D8<>INT(GARANTIAS_II!D8),LEN(TEXT(ABS(GARANTIAS_II!D8),"0"))>3),TRUE)),1,0) -> 0 | E8: =IF(AND(GARANTIAS_II!E8<>"",LEN(GARANTIAS_II!E8)>1),1,0) -> 0 | F8: =IF(AND(GARANTIAS_II!F8<>"",COUNTIF(CL_C_GARANT_ANEXO_AD,GARANTIAS_II!F8)=0),1,0) -> 0 | G8: =IF(AND(GARANTIAS_II!G8<>"",OR(LEN(GARANTIAS_II!G8)>20,COUNTIF(CL_C_GARANT_ANEXO_AF,GARANTIAS_II!G8)=0)),1,0) -> 1 | H8: =IF(AND(GARANTIAS_II!H8<>"",LEN(GARANTIAS_II!H8)>6),1,0) -> 0 | I8: =IF(AND(GARANTIAS_II!I8<>"",NOT(ISNUMBER(GARANTIAS_II!I8))),1,0) -> 0 | J8: =IF(AND(GARANTIAS_II!J8<>"",LEN(GARANTIAS_II!J8)>20),1,0) -> 0 | K8: =IF(AND(GARANTIAS_II!K8<>"",IF(ISNUMBER(GARANTIAS_II!K8),OR(GARANTIAS_II!K8<>ROUND(GARANTIAS_II!K8,2),LEN(TEXT(INT(ABS(GARANTIAS_II!K8)),"0"))>5),TRUE)),1,0) -> 0 | L8: =IF(AND(GARANTIAS_II!L8<>"",IF(ISNUMBER(GARANTIAS_II!L8),OR(GARANTIAS_II!L8<>INT(GARANTIAS_II!L8),LEN(TEXT(ABS(GARANTIAS_II!L8),"0"))>15),TRUE)),1,0) -> 0 | M8: =IF(AND(GARANTIAS_II!M8<>"",COUNTIF(CL_C_GARANT_ANEXO_E,GARANTIAS_II!M8)=0),1,0) -> 0 | N8: =IF(AND(GARANTIAS_II!N8<>"",NOT(ISNUMBER(GARANTIAS_II!N8))),1,0) -> 0
A9: =IF(AND(GARANTIAS_II!A9<>"",OR(LEN(GARANTIAS_II!A9)>1,COUNTIF(CL_C_GARANT_ANEXO_A,GARANTIAS_II!A9)=0)),1,0) -> 0 | B9: =IF(AND(GARANTIAS_II!B9<>"",OR(LEN(GARANTIAS_II!B9)>6,COUNTIF(CL_C_CASFIM,GARANTIAS_II!B9)=0)),1,0) -> 1 | C9: =IF(AND(GARANTIAS_II!C9<>"",LEN(GARANTIAS_II!C9)>20),1,0) -> 0 | D9: =IF(AND(GARANTIAS_II!D9<>"",IF(ISNUMBER(GARANTIAS_II!D9),OR(GARANTIAS_II!D9<>INT(GARANTIAS_II!D9),LEN(TEXT(ABS(GARANTIAS_II!D9),"0"))>3),TRUE)),1,0) -> 0 | E9: =IF(AND(GARANTIAS_II!E9<>"",LEN(GARANTIAS_II!E9)>1),1,0) -> 0 | F9: =IF(AND(GARANTIAS_II!F9<>"",COUNTIF(CL_C_GARANT_ANEXO_AD,GARANTIAS_II!F9)=0),1,0) -> 0 | G9: =IF(AND(GARANTIAS_II!G9<>"",OR(LEN(GARANTIAS_II!G9)>20,COUNTIF(CL_C_GARANT_ANEXO_AF,GARANTIAS_II!G9)=0)),1,0) -> 1 | H9: =IF(AND(GARANTIAS_II!H9<>"",LEN(GARANTIAS_II!H9)>6),1,0) -> 0 | I9: =IF(AND(GARANTIAS_II!I9<>"",NOT(ISNUMBER(GARANTIAS_II!I9))),1,0) -> 0 | J9: =IF(AND(GARANTIAS_II!J9<>"",LEN(GARANTIAS_II!J9)>20),1,0) -> 0 | K9: =IF(AND(GARANTIAS_II!K9<>"",IF(ISNUMBER(GARANTIAS_II!K9),OR(GARANTIAS_II!K9<>ROUND(GARANTIAS_II!K9,2),LEN(TEXT(INT(ABS(GARANTIAS_II!K9)),"0"))>5),TRUE)),1,0) -> 0 | L9: =IF(AND(GARANTIAS_II!L9<>"",IF(ISNUMBER(GARANTIAS_II!L9),OR(GARANTIAS_II!L9<>INT(GARANTIAS_II!L9),LEN(TEXT(ABS(GARANTIAS_II!L9),"0"))>15),TRUE)),1,0) -> 0 | M9: =IF(AND(GARANTIAS_II!M9<>"",COUNTIF(CL_C_GARANT_ANEXO_E,GARANTIAS_II!M9)=0),1,0) -> 0 | N9: =IF(AND(GARANTIAS_II!N9<>"",NOT(ISNUMBER(GARANTIAS_II!N9))),1,0) -> 0
A10: =IF(AND(GARANTIAS_II!A10<>"",OR(LEN(GARANTIAS_II!A10)>1,COUNTIF(CL_C_GARANT_ANEXO_A,GARANTIAS_II!A10)=0)),1,0) -> 1 | B10: =IF(AND(GARANTIAS_II!B10<>"",OR(LEN(GARANTIAS_II!B10)>6,COUNTIF(CL_C_CASFIM,GARANTIAS_II!B10)=0)),1,0) -> 1 | C10: =IF(AND(GARANTIAS_II!C10<>"",LEN(GARANTIAS_II!C10)>20),1,0) -> 0 | D10: =IF(AND(GARANTIAS_II!D10<>"",IF(ISNUMBER(GARANTIAS_II!D10),OR(GARANTIAS_II!D10<>INT(GARANTIAS_II!D10),LEN(TEXT(ABS(GARANTIAS_II!D10),"0"))>3),TRUE)),1,0) -> 0 | E10: =IF(AND(GARANTIAS_II!E10<>"",LEN(GARANTIAS_II!E10)>1),1,0) -> 0 | F10: =IF(AND(GARANTIAS_II!F10<>"",COUNTIF(CL_C_GARANT_ANEXO_AD,GARANTIAS_II!F10)=0),1,0) -> 0 | G10: =IF(AND(GARANTIAS_II!G10<>"",OR(LEN(GARANTIAS_II!G10)>20,COUNTIF(CL_C_GARANT_ANEXO_AF,GARANTIAS_II!G10)=0)),1,0) -> 1 | H10: =IF(AND(GARANTIAS_II!H10<>"",LEN(GARANTIAS_II!H10)>6),1,0) -> 0 | I10: =IF(AND(GARANTIAS_II!I10<>"",NOT(ISNUMBER(GARANTIAS_II!I10))),1,0) -> 0 | J10: =IF(AND(GARANTIAS_II!J10<>"",LEN(GARANTIAS_II!J10)>20),1,0) -> 0 | K10: =IF(AND(GARANTIAS_II!K10<>"",IF(ISNUMBER(GARANTIAS_II!K10),OR(GARANTIAS_II!K10<>ROUND(GARANTIAS_II!K10,2),LEN(TEXT(INT(ABS(GARANTIAS_II!K10)),"0"))>5),TRUE)),1,0) -> 0 | L10: =IF(AND(GARANTIAS_II!L10<>"",IF(ISNUMBER(GARANTIAS_II!L10),OR(GARANTIAS_II!L10<>INT(GARANTIAS_II!L10),LEN(TEXT(ABS(GARANTIAS_II!L10),"0"))>15),TRUE)),1,0) -> 0 | M10: =IF(AND(GARANTIAS_II!M10<>"",COUNTIF(CL_C_GARANT_ANEXO_E,GARANTIAS_II!M10)=0),1,0) -> 0 | N10: =IF(AND(GARANTIAS_II!N10<>"",NOT(ISNUMBER(GARANTIAS_II!N10))),1,0) -> 0
A11: =IF(AND(GARANTIAS_II!A11<>"",OR(LEN(GARANTIAS_II!A11)>1,COUNTIF(CL_C_GARANT_ANEXO_A,GARANTIAS_II!A11)=0)),1,0) -> 1 | B11: =IF(AND(GARANTIAS_II!B11<>"",OR(LEN(GARANTIAS_II!B11)>6,COUNTIF(CL_C_CASFIM,GARANTIAS_II!B11)=0)),1,0) -> 1 | C11: =IF(AND(GARANTIAS_II!C11<>"",LEN(GARANTIAS_II!C11)>20),1,0) -> 0 | D11: =IF(AND(GARANTIAS_II!D11<>"",IF(ISNUMBER(GARANTIAS_II!D11),OR(GARANTIAS_II!D11<>INT(GARANTIAS_II!D11),LEN(TEXT(ABS(GARANTIAS_II!D11),"0"))>3),TRUE)),1,0) -> 0 | E11: =IF(AND(GARANTIAS_II!E11<>"",LEN(GARANTIAS_II!E11)>1),1,0) -> 0 | F11: =IF(AND(GARANTIAS_II!F11<>"",COUNTIF(CL_C_GARANT_ANEXO_AD,GARANTIAS_II!F11)=0),1,0) -> 0 | G11: =IF(AND(GARANTIAS_II!G11<>"",OR(LEN(GARANTIAS_II!G11)>20,COUNTIF(CL_C_GARANT_ANEXO_AF,GARANTIAS_II!G11)=0)),1,0) -> 1 | H11: =IF(AND(GARANTIAS_II!H11<>"",LEN(GARANTIAS_II!H11)>6),1,0) -> 0 | I11: =IF(AND(GARANTIAS_II!I11<>"",NOT(ISNUMBER(GARANTIAS_II!I11))),1,0) -> 0 | J11: =IF(AND(GARANTIAS_II!J11<>"",LEN(GARANTIAS_II!J11)>20),1,0) -> 0 | K11: =IF(AND(GARANTIAS_II!K11<>"",IF(ISNUMBER(GARANTIAS_II!K11),OR(GARANTIAS_II!K11<>ROUND(GARANTIAS_II!K11,2),LEN(TEXT(INT(ABS(GARANTIAS_II!K11)),"0"))>5),TRUE)),1,0) -> 0 | L11: =IF(AND(GARANTIAS_II!L11<>"",IF(ISNUMBER(GARANTIAS_II!L11),OR(GARANTIAS_II!L11<>INT(GARANTIAS_II!L11),LEN(TEXT(ABS(GARANTIAS_II!L11),"0"))>15),TRUE)),1,0) -> 0 | M11: =IF(AND(GARANTIAS_II!M11<>"",COUNTIF(CL_C_GARANT_ANEXO_E,GARANTIAS_II!M11)=0),1,0) -> 0 | N11: =IF(AND(GARANTIAS_II!N11<>"",NOT(ISNUMBER(GARANTIAS_II!N11))),1,0) -> 0
A12: =IF(AND(GARANTIAS_II!A12<>"",OR(LEN(GARANTIAS_II!A12)>1,COUNTIF(CL_C_GARANT_ANEXO_A,GARANTIAS_II!A12)=0)),1,0) -> 0 | B12: =IF(AND(GARANTIAS_II!B12<>"",OR(LEN(GARANTIAS_II!B12)>6,COUNTIF(CL_C_CASFIM,GARANTIAS_II!B12)=0)),1,0) -> 0 | C12: =IF(AND(GARANTIAS_II!C12<>"",LEN(GARANTIAS_II!C12)>20),1,0) -> 0 | D12: =IF(AND(GARANTIAS_II!D12<>"",IF(ISNUMBER(GARANTIAS_II!D12),OR(GARANTIAS_II!D12<>INT(GARANTIAS_II!D12),LEN(TEXT(ABS(GARANTIAS_II!D12),"0"))>3),TRUE)),1,0) -> 0 | E12: =IF(AND(GARANTIAS_II!E12<>"",LEN(GARANTIAS_II!E12)>1),1,0) -> 0 | F12: =IF(AND(GARANTIAS_II!F12<>"",COUNTIF(CL_C_GARANT_ANEXO_AD,GARANTIAS_II!F12)=0),1,0) -> 0 | G12: =IF(AND(GARANTIAS_II!G12<>"",OR(LEN(GARANTIAS_II!G12)>20,COUNTIF(CL_C_GARANT_ANEXO_AF,GARANTIAS_II!G12)=0)),1,0) -> 0 | H12: =IF(AND(GARANTIAS_II!H12<>"",LEN(GARANTIAS_II!H12)>6),1,0) -> 0 | I12: =IF(AND(GARANTIAS_II!I12<>"",NOT(ISNUMBER(GARANTIAS_II!I12))),1,0) -> 0 | J12: =IF(AND(GARANTIAS_II!J12<>"",LEN(GARANTIAS_II!J12)>20),1,0) -> 0 | K12: =IF(AND(GARANTIAS_II!K12<>"",IF(ISNUMBER(GARANTIAS_II!K12),OR(GARANTIAS_II!K12<>ROUND(GARANTIAS_II!K12,2),LEN(TEXT(INT(ABS(GARANTIAS_II!K12)),"0"))>5),TRUE)),1,0) -> 0 | L12: =IF(AND(GARANTIAS_II!L12<>"",IF(ISNUMBER(GARANTIAS_II!L12),OR(GARANTIAS_II!L12<>INT(GARANTIAS_II!L12),LEN(TEXT(ABS(GARANTIAS_II!L12),"0"))>15),TRUE)),1,0) -> 0 | M12: =IF(AND(GARANTIAS_II!M12<>"",COUNTIF(CL_C_GARANT_ANEXO_E,GARANTIAS_II!M12)=0),1,0) -> 0 | N12: =IF(AND(GARANTIAS_II!N12<>"",NOT(ISNUMBER(GARANTIAS_II!N12))),1,0) -> 0
A13: =IF(AND(GARANTIAS_II!A13<>"",OR(LEN(GARANTIAS_II!A13)>1,COUNTIF(CL_C_GARANT_ANEXO_A,GARANTIAS_II!A13)=0)),1,0) -> 0 | B13: =IF(AND(GARANTIAS_II!B13<>"",OR(LEN(GARANTIAS_II!B13)>6,COUNTIF(CL_C_CASFIM,GARANTIAS_II!B13)=0)),1,0) -> 0 | C13: =IF(AND(GARANTIAS_II!C13<>"",LEN(GARANTIAS_II!C13)>20),1,0) -> 0 | D13: =IF(AND(GARANTIAS_II!D13<>"",IF(ISNUMBER(GARANTIAS_II!D13),OR(GARANTIAS_II!D13<>INT(GARANTIAS_II!D13),LEN(TEXT(ABS(GARANTIAS_II!D13),"0"))>3),TRUE)),1,0) -> 0 | E13: =IF(AND(GARANTIAS_II!E13<>"",LEN(GARANTIAS_II!E13)>1),1,0) -> 0 | F13: =IF(AND(GARANTIAS_II!F13<>"",COUNTIF(CL_C_GARANT_ANEXO_AD,GARANTIAS_II!F13)=0),1,0) -> 0 | G13: =IF(AND(GARANTIAS_II!G13<>"",OR(LEN(GARANTIAS_II!G13)>20,COUNTIF(CL_C_GARANT_ANEXO_AF,GARANTIAS_II!G13)=0)),1,0) -> 0 | H13: =IF(AND(GARANTIAS_II!H13<>"",LEN(GARANTIAS_II!H13)>6),1,0) -> 0 | I13: =IF(AND(GARANTIAS_II!I13<>"",NOT(ISNUMBER(GARANTIAS_II!I13))),1,0) -> 0 | J13: =IF(AND(GARANTIAS_II!J13<>"",LEN(GARANTIAS_II!J13)>20),1,0) -> 0 | K13: =IF(AND(GARANTIAS_II!K13<>"",IF(ISNUMBER(GARANTIAS_II!K13),OR(GARANTIAS_II!K13<>ROUND(GARANTIAS_II!K13,2),LEN(TEXT(INT(ABS(GARANTIAS_II!K13)),"0"))>5),TRUE)),1,0) -> 0 | L13: =IF(AND(GARANTIAS_II!L13<>"",IF(ISNUMBER(GARANTIAS_II!L13),OR(GARANTIAS_II!L13<>INT(GARANTIAS_II!L13),LEN(TEXT(ABS(GARANTIAS_II!L13),"0"))>15),TRUE)),1,0) -> 0 | M13: =IF(AND(GARANTIAS_II!M13<>"",COUNTIF(CL_C_GARANT_ANEXO_E,GARANTIAS_II!M13)=0),1,0) -> 0 | N13: =IF(AND(GARANTIAS_II!N13<>"",NOT(ISNUMBER(GARANTIAS_II!N13))),1,0) -> 0
... A201: =IF(AND(GARANTIAS_II!A201<>"",OR(LEN(GARANTIAS_II!A201)>1,COUNTIF(CL_C_GARANT_ANEXO_A,GARANTIAS_II!A201)=0)),1,0) -> 0 | B201: =IF(AND(GARANTIAS_II!B201<>"",OR(LEN(GARANTIAS_II!B201)>6,COUNTIF(CL_C_CASFIM,GARANTIAS_II!B201)=0)),1,0) -> 0 | C201: =IF(AND(GARANTIAS_II!C201<>"",LEN(GARANTIAS_II!C201)>20),1,0) -> 0 | D201: =IF(AND(GARANTIAS_II!D201<>"",IF(ISNUMBER(GARANTIAS_II!D201),OR(GARANTIAS_II!D201<>INT(GARANTIAS_II!D201),LEN(TEXT(ABS(GARANTIAS_II!D201),"0"))>3),TRUE)),1,0) -> 0 | E201: =IF(AND(GARANTIAS_II!E201<>"",LEN(GARANTIAS_II!E201)>1),1,0) -> 0 | F201: =IF(AND(GARANTIAS_II!F201<>"",COUNTIF(CL_C_GARANT_ANEXO_AD,GARANTIAS_II!F201)=0),1,0) -> 0 | G201: =IF(AND(GARANTIAS_II!G201<>"",OR(LEN(GARANTIAS_II!G201)>20,COUNTIF(CL_C_GARANT_ANEXO_AF,GARANTIAS_II!G201)=0)),1,0) -> 0 | H201: =IF(AND(GARANTIAS_II!H201<>"",LEN(GARANTIAS_II!H201)>6),1,0) -> 0 | I201: =IF(AND(GARANTIAS_II!I201<>"",NOT(ISNUMBER(GARANTIAS_II!I201))),1,0) -> 0 | J201: =IF(AND(GARANTIAS_II!J201<>"",LEN(GARANTIAS_II!J201)>20),1,0) -> 0 | K201: =IF(AND(GARANTIAS_II!K201<>"",IF(ISNUMBER(GARANTIAS_II!K201),OR(GARANTIAS_II!K201<>ROUND(GARANTIAS_II!K201,2),LEN(TEXT(INT(ABS(GARANTIAS_II!K201)),"0"))>5),TRUE)),1,0) -> 0 | L201: =IF(AND(GARANTIAS_II!L201<>"",IF(ISNUMBER(GARANTIAS_II!L201),OR(GARANTIAS_II!L201<>INT(GARANTIAS_II!L201),LEN(TEXT(ABS(GARANTIAS_II!L201),"0"))>15),TRUE)),1,0) -> 0 | M201: =IF(AND(GARANTIAS_II!M201<>"",COUNTIF(CL_C_GARANT_ANEXO_E,GARANTIAS_II!M201)=0),1,0) -> 0 | N201: =IF(AND(GARANTIAS_II!N201<>"",NOT(ISNUMBER(GARANTIAS_II!N201))),1,0) -> 0
