Workbook
Name CL_TIPO_VALOR: CAT_TIPO_VALOR!$A$2:$A$5
Name CL_MONEDA: CAT_MONEDA!$A$2:$A$171
Name CL_ID_PAGOS_REAL: CAT_ID_PAGOS_REAL!$A$2:$A$3
Name CL_CASFIM: CAT_CASFIM!$A$2:$A$40063
Name CL_CARACT_LIQ: CAT_CARACT_LIQ!$A$2:$A$4

Sheet VALIDACION
A1: RESUMEN DE VALIDACIÓN
A2: Total celdas con error de formato: | C2: =SUM(CHK!A2:J201)
A3: Estado: | C3: =IF(C2=0,"✔ SIN ERRORES DE FORMATO","✖ REVISAR: "&C2&" celda(s) marcada(s) en rojo")
A5: Orden | B5: Campo | C5: Tipo | D5: Long | E5: Catálogo | F5: # Errores | G5: # Vacíos (obligatorio)
A6: 1 | B6: FECHA_LIQ | C6: FECHA | D6: AAAA/MM/DD | E6: — | F6: =SUM(CHK!A2:A201) | G6: =COUNTBLANK('LID_CORRESPONSALES'!A2:A201)
A7: 2 | B7: HORA_LIQ | C7: TEXTO | D7: 5 | E7: — | F7: =SUM(CHK!B2:B201) | G7: =COUNTBLANK('LID_CORRESPONSALES'!B2:B201)
A8: 3 | B8: TIPO_VALOR | C8: NUMERICO | D8: 2,0 | E8: Tipo_Valor | F8: =SUM(CHK!C2:C201) | G8: =COUNTBLANK('LID_CORRESPONSALES'!C2:C201)
A9: 4 | B9: MONTO_PAGOS | C9: NUMERICO | D9: 12,0 | E9: — | F9: =SUM(CHK!D2:D201) | G9: =COUNTBLANK('LID_CORRESPONSALES'!D2:D201)
A10: 5 | B10: MONEDA | C10: TEXTO | D10: 3 | E10: Moneda | F10: =SUM(CHK!E2:E201) | G10: =COUNTBLANK('LID_CORRESPONSALES'!E2:E201)
A11: 6 | B11: ID_PAGOS_REAL | C11: NUMERICO | D11: 2,0 | E11: Id_Pagos_Real | F11: =SUM(CHK!F2:F201) | G11: =COUNTBLANK('LID_CORRESPONSALES'!F2:F201)
A12: 7 | B12: CONT_CORRESPONSAL | C12: TEXTO | D12: 6 | E12: CASFIM | F12: =SUM(CHK!G2:G201) | G12: =COUNTBLANK('LID_CORRESPONSALES'!G2:G201)
A13: 8 | B13: CONT_RECEPTORA | C13: TEXTO | D13: 6 | E13: CASFIM | F13: =SUM(CHK!H2:H201) | G13: =COUNTBLANK('LID_CORRESPONSALES'!H2:H201)
A14: 9 | B14: CARACT_LIQUIDACION | C14: NUMERICO | D14: 2,0 | E14: Caract_liq | F14: =SUM(CHK!I2:I201) | G14: =COUNTBLANK('LID_CORRESPONSALES'!I2:I201)
A15: 10 | B15: FECHA_INFO | C15: FECHA | D15: AAAA/MM/DD | E15: — | F15: =SUM(CHK!J2:J201) | G15: =COUNTBLANK('LID_CORRESPONSALES'!J2:J201)

Sheet LID_CORRESPONSALES
A1: FECHA_LIQ | B1: HORA_LIQ | C1: TIPO_VALOR | D1: MONTO_PAGOS | E1: MONEDA | F1: ID_PAGOS_REAL | G1: CONT_CORRESPONSAL | H1: CONT_RECEPTORA | I1: CARACT_LIQUIDACION | J1: FECHA_INFO

Sheet CAT_TIPO_VALOR
A1: Clave | B1: Descripcion
A2: 1 | B2: Valor máximo durante el día
A3: 2 | B3: Segundo valor máximo durante el día
A4: 3 | B4: Tercer valor máximo durante el día
A5: 10 | B5: Total de pagos durante el día

Sheet CAT_MONEDA
A1: Clave | B1: Descripcion
A2: AFN | B2: 971
A3: EUR | B3: 978
A4: ALL | B4: 8
A5: DZD | B5: 12
A6: USD | B6: 840
A7: AOA | B7: 973
A8: XCD | B8: 951
A9: ARS | B9: 32
A10: AMD | B10: 51
A11: AWG | B11: 533
A12: AUD | B12: 36
... A171: ZWL | B171: 932

Sheet CAT_ID_PAGOS_REAL
A1: Clave | B1: Descripcion
A2: 0 | B2: Sin pagos realizados
A3: 1 | B3: Con pagos realizados

Sheet CAT_CASFIM
A1: Clave | B1: Descripcion
A2: 000111 | B2: AGENTE DE CALCULO Y/O LIQUIDADOR
A3: 000750 | B3: OTROS INTERMEDIARIOS FINANCIEROS MEXICANOS
A4: 000760 | B4: GOBIERNO FEDERAL EXCEPTO LA SHCP
A5: 000770 | B5: GOBIERNOS DE LOS ESTADOS (EXCLUYENDO AL DEL D.F.) Y DE LOS MUNICIPIOS.
A6: 000775 | B6: GOBIERNO DEL DISTRITO FEDERAL
A7: 000780 | B7: FONDOS DE RESERVA PARA PENSIONES JUBILACIONES Y DEMAS PRESTACIONES DEL PERSONAL DE LA PROPIA INSTITUCION
A8: 000790 | B8: ARREND FACTORAJES CASAS CAMBIO SOFOLES Y AFIANZADORAS DEL GRUPO FINANCIERO AL QUE PERTENECE LA INSTITUCION O FILIALES FINANCIERAS DE LA INSTITUCION
A9: 000791 | B9: ARRENDADORAS FINANCIERAS PRIVADAS DEL GRUPO FINANCIERO AL QUE PERTENECE LA INSTITUCION O FILIALES FINANCIERAS DE LA INSTITUCION
A10: 000792 | B10: EMPRESAS DE FACTORAJE DEL GRUPO FINANCIERO AL QUE PERTENECE LA INSTITUCION O FILIALES FINANCIERAS DE LA INSTITUCION
A11: 000793 | B11: CASAS DE CAMBIO DEL GRUPO FINANCIERO AL QUE PERTENECE LA INSTITUCION O FILIALES FINANCIERAS DE LA INSTITUCION
A12: 000794 | B12: SOFOLES DEL GRUPO FINANCIERO AL QUE PERTENECE LA INSTITUCION O FILIALES FINANCIERAS DE LA INSTITUCION
... A951: 052326 | B951: ING 5 SA DE CV
A952: 052327
A953: 052328 | B953: INVERCAP DEUDA PERSONAS FISICAS FOMENTO AL AHORRO
A954: 052329 | B954: INVERCAP FONDO GLOBAL MEXICANO
A955: 052330 | B955: INVERCAP DEUDA PERSONAS FISICAS PATRIMONIAL
A956: 052331 | B956: INVERCAP PLUS
A957: 052332 | B957: FONDO BBVA BANCOMER DEUDA DOLARES
A958: 052333 | B958: SURA USD SA DE CV SIID
A959: 052334 | B959: FONDO ACTINVER ACTIVO PATRIMONIAL
A960: 052335 | B960: PRUDENTIAL DOLARES DE LARGO PLAZO PLUS
A961: 052336 | B961: IN28 SA DE CV
A962: 052337 | B962: INEM
A963: 052338 | B963: INFIS
A964: 052339 | B964: INGUBER
... A1197: 052574 | B1197: Z CAP 5
A1198: 052575
A1199: 052576 | B1199: HSBCD10 SA DE CV
A1200: 052577 | B1200: HSBC FO SA DE CV SIID
A1201: 052578 | B1201: NORTESELECTIVO
A1202: 052579 | B1202: FONDO INTERACCIONES 7 SA DE CV
A1203: 052580 | B1203: SURA SOLUCIONES 1 SA DE CV SIRD
A1204: 052581 | B1204: SURA SOLUCIONES 2 SA DE CV SIRV
A1205: 052582 | B1205: SURA SOLUCIONES 3 SA DE CV SIRV
A1206: 052583 | B1206: SURA SOLUCIONES 4 SA DE CV SIRV
A1207: 052584 | B1207: SURA SOLUCIONES 5 SA DE CV SIRV
A1208: 052585 | B1208: NORTEEQUILIBRADO SA DE CV SIRV
A1209: 052586 | B1209: GBM FONDO DE INVERSIONES DISCRECIONALES
A1210: 052587 | B1210: GBM INVERSIONES EN INDICES INTERNACIONALES DE RENTA VARIABLE SA DE CV
...

Sheet CAT_CARACT_LIQ
A1: Clave | B1: Descripcion
A2: 1 | B2: Liquidaciones en tiempo y forma
A3: 2 | B3: Liquidaciones retrasadas o no aplicadas
A4: 3 | B4: Liquidaciones a través de corresponsales

Sheet CHK
A2: =IF(AND('LID_CORRESPONSALES'!A2<>"",NOT(ISNUMBER('LID_CORRESPONSALES'!A2))),1,0) | B2: =IF(AND('LID_CORRESPONSALES'!B2<>"",LEN('LID_CORRESPONSALES'!B2)>5),1,0) | C2: =IF(AND('LID_CORRESPONSALES'!C2<>"",COUNTIF(CL_TIPO_VALOR,'LID_CORRESPONSALES'!C2)=0),1,0) | D2: =IF(AND('LID_CORRESPONSALES'!D2<>"",IF(ISNUMBER('LID_CORRESPONSALES'!D2),OR('LID_CORRESPONSALES'!D2<>ROUND('LID_CORRESPONSALES'!D2,0),LEN(TEXT(INT(ABS('LID_CORRESPONSALES'!D2)),"0"))>12),TRUE)),1,0) | E2: =IF(AND('LID_CORRESPONSALES'!E2<>"",OR(LEN('LID_CORRESPONSALES'!E2)>3,COUNTIF(CL_MONEDA,'LID_CORRESPONSALES'!E2)=0)),1,0) | F2: =IF(AND('LID_CORRESPONSALES'!F2<>"",COUNTIF(CL_ID_PAGOS_REAL,'LID_CORRESPONSALES'!F2)=0),1,0) | G2: =IF(AND('LID_CORRESPONSALES'!G2<>"",OR(LEN('LID_CORRESPONSALES'!G2)>6,COUNTIF(CL_CASFIM,'LID_CORRESPONSALES'!G2)=0)),1,0) | H2: =IF(AND('LID_CORRESPONSALES'!H2<>"",OR(LEN('LID_CORRESPONSALES'!H2)>6,COUNTIF(CL_CASFIM,'LID_CORRESPONSALES'!H2)=0)),1,0) | I2: =IF(AND('LID_CORRESPONSALES'!I2<>"",COUNTIF(CL_CARACT_LIQ,'LID_CORRESPONSALES'!I2)=0),1,0) | J2: =IF(AND('LID_CORRESPONSALES'!J2<>"",NOT(ISNUMBER('LID_CORRESPONSALES'!J2))),1,0)
A3: =IF(AND('LID_CORRESPONSALES'!A3<>"",NOT(ISNUMBER('LID_CORRESPONSALES'!A3))),1,0) | B3: =IF(AND('LID_CORRESPONSALES'!B3<>"",LEN('LID_CORRESPONSALES'!B3)>5),1,0) | C3: =IF(AND('LID_CORRESPONSALES'!C3<>"",COUNTIF(CL_TIPO_VALOR,'LID_CORRESPONSALES'!C3)=0),1,0) | D3: =IF(AND('LID_CORRESPONSALES'!D3<>"",IF(ISNUMBER('LID_CORRESPONSALES'!D3),OR('LID_CORRESPONSALES'!D3<>ROUND('LID_CORRESPONSALES'!D3,0),LEN(TEXT(INT(ABS('LID_CORRESPONSALES'!D3)),"0"))>12),TRUE)),1,0) | E3: =IF(AND('LID_CORRESPONSALES'!E3<>"",OR(LEN('LID_CORRESPONSALES'!E3)>3,COUNTIF(CL_MONEDA,'LID_CORRESPONSALES'!E3)=0)),1,0) | F3: =IF(AND('LID_CORRESPONSALES'!F3<>"",COUNTIF(CL_ID_PAGOS_REAL,'LID_CORRESPONSALES'!F3)=0),1,0) | G3: =IF(AND('LID_CORRESPONSALES'!G3<>"",OR(LEN('LID_CORRESPONSALES'!G3)>6,COUNTIF(CL_CASFIM,'LID_CORRESPONSALES'!G3)=0)),1,0) | H3: =IF(AND('LID_CORRESPONSALES'!H3<>"",OR(LEN('LID_CORRESPONSALES'!H3)>6,COUNTIF(CL_CASFIM,'LID_CORRESPONSALES'!H3)=0)),1,0) | I3: =IF(AND('LID_CORRESPONSALES'!I3<>"",COUNTIF(CL_CARACT_LIQ,'LID_CORRESPONSALES'!I3)=0),1,0) | J3: =IF(AND('LID_CORRESPONSALES'!J3<>"",NOT(ISNUMBER('LID_CORRESPONSALES'!J3))),1,0)
A4: =IF(AND('LID_CORRESPONSALES'!A4<>"",NOT(ISNUMBER('LID_CORRESPONSALES'!A4))),1,0) | B4: =IF(AND('LID_CORRESPONSALES'!B4<>"",LEN('LID_CORRESPONSALES'!B4)>5),1,0) | C4: =IF(AND('LID_CORRESPONSALES'!C4<>"",COUNTIF(CL_TIPO_VALOR,'LID_CORRESPONSALES'!C4)=0),1,0) | D4: =IF(AND('LID_CORRESPONSALES'!D4<>"",IF(ISNUMBER('LID_CORRESPONSALES'!D4),OR('LID_CORRESPONSALES'!D4<>ROUND('LID_CORRESPONSALES'!D4,0),LEN(TEXT(INT(ABS('LID_CORRESPONSALES'!D4)),"0"))>12),TRUE)),1,0) | E4: =IF(AND('LID_CORRESPONSALES'!E4<>"",OR(LEN('LID_CORRESPONSALES'!E4)>3,COUNTIF(CL_MONEDA,'LID_CORRESPONSALES'!E4)=0)),1,0) | F4: =IF(AND('LID_CORRESPONSALES'!F4<>"",COUNTIF(CL_ID_PAGOS_REAL,'LID_CORRESPONSALES'!F4)=0),1,0) | G4: =IF(AND('LID_CORRESPONSALES'!G4<>"",OR(LEN('LID_CORRESPONSALES'!G4)>6,COUNTIF(CL_CASFIM,'LID_CORRESPONSALES'!G4)=0)),1,0) | H4: =IF(AND('LID_CORRESPONSALES'!H4<>"",OR(LEN('LID_CORRESPONSALES'!H4)>6,COUNTIF(CL_CASFIM,'LID_CORRESPONSALES'!H4)=0)),1,0) | I4: =IF(AND('LID_CORRESPONSALES'!I4<>"",COUNTIF(CL_CARACT_LIQ,'LID_CORRESPONSALES'!I4)=0),1,0) | J4: =IF(AND('LID_CORRESPONSALES'!J4<>"",NOT(ISNUMBER('LID_CORRESPONSALES'!J4))),1,0)
A5: =IF(AND('LID_CORRESPONSALES'!A5<>"",NOT(ISNUMBER('LID_CORRESPONSALES'!A5))),1,0) | B5: =IF(AND('LID_CORRESPONSALES'!B5<>"",LEN('LID_CORRESPONSALES'!B5)>5),1,0) | C5: =IF(AND('LID_CORRESPONSALES'!C5<>"",COUNTIF(CL_TIPO_VALOR,'LID_CORRESPONSALES'!C5)=0),1,0) | D5: =IF(AND('LID_CORRESPONSALES'!D5<>"",IF(ISNUMBER('LID_CORRESPONSALES'!D5),OR('LID_CORRESPONSALES'!D5<>ROUND('LID_CORRESPONSALES'!D5,0),LEN(TEXT(INT(ABS('LID_CORRESPONSALES'!D5)),"0"))>12),TRUE)),1,0) | E5: =IF(AND('LID_CORRESPONSALES'!E5<>"",OR(LEN('LID_CORRESPONSALES'!E5)>3,COUNTIF(CL_MONEDA,'LID_CORRESPONSALES'!E5)=0)),1,0) | F5: =IF(AND('LID_CORRESPONSALES'!F5<>"",COUNTIF(CL_ID_PAGOS_REAL,'LID_CORRESPONSALES'!F5)=0),1,0) | G5: =IF(AND('LID_CORRESPONSALES'!G5<>"",OR(LEN('LID_CORRESPONSALES'!G5)>6,COUNTIF(CL_CASFIM,'LID_CORRESPONSALES'!G5)=0)),1,0) | H5: =IF(AND('LID_CORRESPONSALES'!H5<>"",OR(LEN('LID_CORRESPONSALES'!H5)>6,COUNTIF(CL_CASFIM,'LID_CORRESPONSALES'!H5)=0)),1,0) | I5: =IF(AND('LID_CORRESPONSALES'!I5<>"",COUNTIF(CL_CARACT_LIQ,'LID_CORRESPONSALES'!I5)=0),1,0) | J5: =IF(AND('LID_CORRESPONSALES'!J5<>"",NOT(ISNUMBER('LID_CORRESPONSALES'!J5))),1,0)
A6: =IF(AND('LID_CORRESPONSALES'!A6<>"",NOT(ISNUMBER('LID_CORRESPONSALES'!A6))),1,0) | B6: =IF(AND('LID_CORRESPONSALES'!B6<>"",LEN('LID_CORRESPONSALES'!B6)>5),1,0) | C6: =IF(AND('LID_CORRESPONSALES'!C6<>"",COUNTIF(CL_TIPO_VALOR,'LID_CORRESPONSALES'!C6)=0),1,0) | D6: =IF(AND('LID_CORRESPONSALES'!D6<>"",IF(ISNUMBER('LID_CORRESPONSALES'!D6),OR('LID_CORRESPONSALES'!D6<>ROUND('LID_CORRESPONSALES'!D6,0),LEN(TEXT(INT(ABS('LID_CORRESPONSALES'!D6)),"0"))>12),TRUE)),1,0) | E6: =IF(AND('LID_CORRESPONSALES'!E6<>"",OR(LEN('LID_CORRESPONSALES'!E6)>3,COUNTIF(CL_MONEDA,'LID_CORRESPONSALES'!E6)=0)),1,0) | F6: =IF(AND('LID_CORRESPONSALES'!F6<>"",COUNTIF(CL_ID_PAGOS_REAL,'LID_CORRESPONSALES'!F6)=0),1,0) | G6: =IF(AND('LID_CORRESPONSALES'!G6<>"",OR(LEN('LID_CORRESPONSALES'!G6)>6,COUNTIF(CL_CASFIM,'LID_CORRESPONSALES'!G6)=0)),1,0) | H6: =IF(AND('LID_CORRESPONSALES'!H6<>"",OR(LEN('LID_CORRESPONSALES'!H6)>6,COUNTIF(CL_CASFIM,'LID_CORRESPONSALES'!H6)=0)),1,0) | I6: =IF(AND('LID_CORRESPONSALES'!I6<>"",COUNTIF(CL_CARACT_LIQ,'LID_CORRESPONSALES'!I6)=0),1,0) | J6: =IF(AND('LID_CORRESPONSALES'!J6<>"",NOT(ISNUMBER('LID_CORRESPONSALES'!J6))),1,0)
A7: =IF(AND('LID_CORRESPONSALES'!A7<>"",NOT(ISNUMBER('LID_CORRESPONSALES'!A7))),1,0) | B7: =IF(AND('LID_CORRESPONSALES'!B7<>"",LEN('LID_CORRESPONSALES'!B7)>5),1,0) | C7: =IF(AND('LID_CORRESPONSALES'!C7<>"",COUNTIF(CL_TIPO_VALOR,'LID_CORRESPONSALES'!C7)=0),1,0) | D7: =IF(AND('LID_CORRESPONSALES'!D7<>"",IF(ISNUMBER('LID_CORRESPONSALES'!D7),OR('LID_CORRESPONSALES'!D7<>ROUND('LID_CORRESPONSALES'!D7,0),LEN(TEXT(INT(ABS('LID_CORRESPONSALES'!D7)),"0"))>12),TRUE)),1,0) | E7: =IF(AND('LID_CORRESPONSALES'!E7<>"",OR(LEN('LID_CORRESPONSALES'!E7)>3,COUNTIF(CL_MONEDA,'LID_CORRESPONSALES'!E7)=0)),1,0) | F7: =IF(AND('LID_CORRESPONSALES'!F7<>"",COUNTIF(CL_ID_PAGOS_REAL,'LID_CORRESPONSALES'!F7)=0),1,0) | G7: =IF(AND('LID_CORRESPONSALES'!G7<>"",OR(LEN('LID_CORRESPONSALES'!G7)>6,COUNTIF(CL_CASFIM,'LID_CORRESPONSALES'!G7)=0)),1,0) | H7: =IF(AND('LID_CORRESPONSALES'!H7<>"",OR(LEN('LID_CORRESPONSALES'!H7)>6,COUNTIF(CL_CASFIM,'LID_CORRESPONSALES'!H7)=0)),1,0) | I7: =IF(AND('LID_CORRESPONSALES'!I7<>"",COUNTIF(CL_CARACT_LIQ,'LID_CORRESPONSALES'!I7)=0),1,0) | J7: =IF(AND('LID_CORRESPONSALES'!J7<>"",NOT(ISNUMBER('LID_CORRESPONSALES'!J7))),1,0)
A8: =IF(AND('LID_CORRESPONSALES'!A8<>"",NOT(ISNUMBER('LID_CORRESPONSALES'!A8))),1,0) | B8: =IF(AND('LID_CORRESPONSALES'!B8<>"",LEN('LID_CORRESPONSALES'!B8)>5),1,0) | C8: =IF(AND('LID_CORRESPONSALES'!C8<>"",COUNTIF(CL_TIPO_VALOR,'LID_CORRESPONSALES'!C8)=0),1,0) | D8: =IF(AND('LID_CORRESPONSALES'!D8<>"",IF(ISNUMBER('LID_CORRESPONSALES'!D8),OR('LID_CORRESPONSALES'!D8<>ROUND('LID_CORRESPONSALES'!D8,0),LEN(TEXT(INT(ABS('LID_CORRESPONSALES'!D8)),"0"))>12),TRUE)),1,0) | E8: =IF(AND('LID_CORRESPONSALES'!E8<>"",OR(LEN('LID_CORRESPONSALES'!E8)>3,COUNTIF(CL_MONEDA,'LID_CORRESPONSALES'!E8)=0)),1,0) | F8: =IF(AND('LID_CORRESPONSALES'!F8<>"",COUNTIF(CL_ID_PAGOS_REAL,'LID_CORRESPONSALES'!F8)=0),1,0) | G8: =IF(AND('LID_CORRESPONSALES'!G8<>"",OR(LEN('LID_CORRESPONSALES'!G8)>6,COUNTIF(CL_CASFIM,'LID_CORRESPONSALES'!G8)=0)),1,0) | H8: =IF(AND('LID_CORRESPONSALES'!H8<>"",OR(LEN('LID_CORRESPONSALES'!H8)>6,COUNTIF(CL_CASFIM,'LID_CORRESPONSALES'!H8)=0)),1,0) | I8: =IF(AND('LID_CORRESPONSALES'!I8<>"",COUNTIF(CL_CARACT_LIQ,'LID_CORRESPONSALES'!I8)=0),1,0) | J8: =IF(AND('LID_CORRESPONSALES'!J8<>"",NOT(ISNUMBER('LID_CORRESPONSALES'!J8))),1,0)
A9: =IF(AND('LID_CORRESPONSALES'!A9<>"",NOT(ISNUMBER('LID_CORRESPONSALES'!A9))),1,0) | B9: =IF(AND('LID_CORRESPONSALES'!B9<>"",LEN('LID_CORRESPONSALES'!B9)>5),1,0) | C9: =IF(AND('LID_CORRESPONSALES'!C9<>"",COUNTIF(CL_TIPO_VALOR,'LID_CORRESPONSALES'!C9)=0),1,0) | D9: =IF(AND('LID_CORRESPONSALES'!D9<>"",IF(ISNUMBER('LID_CORRESPONSALES'!D9),OR('LID_CORRESPONSALES'!D9<>ROUND('LID_CORRESPONSALES'!D9,0),LEN(TEXT(INT(ABS('LID_CORRESPONSALES'!D9)),"0"))>12),TRUE)),1,0) | E9: =IF(AND('LID_CORRESPONSALES'!E9<>"",OR(LEN('LID_CORRESPONSALES'!E9)>3,COUNTIF(CL_MONEDA,'LID_CORRESPONSALES'!E9)=0)),1,0) | F9: =IF(AND('LID_CORRESPONSALES'!F9<>"",COUNTIF(CL_ID_PAGOS_REAL,'LID_CORRESPONSALES'!F9)=0),1,0) | G9: =IF(AND('LID_CORRESPONSALES'!G9<>"",OR(LEN('LID_CORRESPONSALES'!G9)>6,COUNTIF(CL_CASFIM,'LID_CORRESPONSALES'!G9)=0)),1,0) | H9: =IF(AND('LID_CORRESPONSALES'!H9<>"",OR(LEN('LID_CORRESPONSALES'!H9)>6,COUNTIF(CL_CASFIM,'LID_CORRESPONSALES'!H9)=0)),1,0) | I9: =IF(AND('LID_CORRESPONSALES'!I9<>"",COUNTIF(CL_CARACT_LIQ,'LID_CORRESPONSALES'!I9)=0),1,0) | J9: =IF(AND('LID_CORRESPONSALES'!J9<>"",NOT(ISNUMBER('LID_CORRESPONSALES'!J9))),1,0)
A10: =IF(AND('LID_CORRESPONSALES'!A10<>"",NOT(ISNUMBER('LID_CORRESPONSALES'!A10))),1,0) | B10: =IF(AND('LID_CORRESPONSALES'!B10<>"",LEN('LID_CORRESPONSALES'!B10)>5),1,0) | C10: =IF(AND('LID_CORRESPONSALES'!C10<>"",COUNTIF(CL_TIPO_VALOR,'LID_CORRESPONSALES'!C10)=0),1,0) | D10: =IF(AND('LID_CORRESPONSALES'!D10<>"",IF(ISNUMBER('LID_CORRESPONSALES'!D10),OR('LID_CORRESPONSALES'!D10<>ROUND('LID_CORRESPONSALES'!D10,0),LEN(TEXT(INT(ABS('LID_CORRESPONSALES'!D10)),"0"))>12),TRUE)),1,0) | E10: =IF(AND('LID_CORRESPONSALES'!E10<>"",OR(LEN('LID_CORRESPONSALES'!E10)>3,COUNTIF(CL_MONEDA,'LID_CORRESPONSALES'!E10)=0)),1,0) | F10: =IF(AND('LID_CORRESPONSALES'!F10<>"",COUNTIF(CL_ID_PAGOS_REAL,'LID_CORRESPONSALES'!F10)=0),1,0) | G10: =IF(AND('LID_CORRESPONSALES'!G10<>"",OR(LEN('LID_CORRESPONSALES'!G10)>6,COUNTIF(CL_CASFIM,'LID_CORRESPONSALES'!G10)=0)),1,0) | H10: =IF(AND('LID_CORRESPONSALES'!H10<>"",OR(LEN('LID_CORRESPONSALES'!H10)>6,COUNTIF(CL_CASFIM,'LID_CORRESPONSALES'!H10)=0)),1,0) | I10: =IF(AND('LID_CORRESPONSALES'!I10<>"",COUNTIF(CL_CARACT_LIQ,'LID_CORRESPONSALES'!I10)=0),1,0) | J10: =IF(AND('LID_CORRESPONSALES'!J10<>"",NOT(ISNUMBER('LID_CORRESPONSALES'!J10))),1,0)
A11: =IF(AND('LID_CORRESPONSALES'!A11<>"",NOT(ISNUMBER('LID_CORRESPONSALES'!A11))),1,0) | B11: =IF(AND('LID_CORRESPONSALES'!B11<>"",LEN('LID_CORRESPONSALES'!B11)>5),1,0) | C11: =IF(AND('LID_CORRESPONSALES'!C11<>"",COUNTIF(CL_TIPO_VALOR,'LID_CORRESPONSALES'!C11)=0),1,0) | D11: =IF(AND('LID_CORRESPONSALES'!D11<>"",IF(ISNUMBER('LID_CORRESPONSALES'!D11),OR('LID_CORRESPONSALES'!D11<>ROUND('LID_CORRESPONSALES'!D11,0),LEN(TEXT(INT(ABS('LID_CORRESPONSALES'!D11)),"0"))>12),TRUE)),1,0) | E11: =IF(AND('LID_CORRESPONSALES'!E11<>"",OR(LEN('LID_CORRESPONSALES'!E11)>3,COUNTIF(CL_MONEDA,'LID_CORRESPONSALES'!E11)=0)),1,0) | F11: =IF(AND('LID_CORRESPONSALES'!F11<>"",COUNTIF(CL_ID_PAGOS_REAL,'LID_CORRESPONSALES'!F11)=0),1,0) | G11: =IF(AND('LID_CORRESPONSALES'!G11<>"",OR(LEN('LID_CORRESPONSALES'!G11)>6,COUNTIF(CL_CASFIM,'LID_CORRESPONSALES'!G11)=0)),1,0) | H11: =IF(AND('LID_CORRESPONSALES'!H11<>"",OR(LEN('LID_CORRESPONSALES'!H11)>6,COUNTIF(CL_CASFIM,'LID_CORRESPONSALES'!H11)=0)),1,0) | I11: =IF(AND('LID_CORRESPONSALES'!I11<>"",COUNTIF(CL_CARACT_LIQ,'LID_CORRESPONSALES'!I11)=0),1,0) | J11: =IF(AND('LID_CORRESPONSALES'!J11<>"",NOT(ISNUMBER('LID_CORRESPONSALES'!J11))),1,0)
A12: =IF(AND('LID_CORRESPONSALES'!A12<>"",NOT(ISNUMBER('LID_CORRESPONSALES'!A12))),1,0) | B12: =IF(AND('LID_CORRESPONSALES'!B12<>"",LEN('LID_CORRESPONSALES'!B12)>5),1,0) | C12: =IF(AND('LID_CORRESPONSALES'!C12<>"",COUNTIF(CL_TIPO_VALOR,'LID_CORRESPONSALES'!C12)=0),1,0) | D12: =IF(AND('LID_CORRESPONSALES'!D12<>"",IF(ISNUMBER('LID_CORRESPONSALES'!D12),OR('LID_CORRESPONSALES'!D12<>ROUND('LID_CORRESPONSALES'!D12,0),LEN(TEXT(INT(ABS('LID_CORRESPONSALES'!D12)),"0"))>12),TRUE)),1,0) | E12: =IF(AND('LID_CORRESPONSALES'!E12<>"",OR(LEN('LID_CORRESPONSALES'!E12)>3,COUNTIF(CL_MONEDA,'LID_CORRESPONSALES'!E12)=0)),1,0) | F12: =IF(AND('LID_CORRESPONSALES'!F12<>"",COUNTIF(CL_ID_PAGOS_REAL,'LID_CORRESPONSALES'!F12)=0),1,0) | G12: =IF(AND('LID_CORRESPONSALES'!G12<>"",OR(LEN('LID_CORRESPONSALES'!G12)>6,COUNTIF(CL_CASFIM,'LID_CORRESPONSALES'!G12)=0)),1,0) | H12: =IF(AND('LID_CORRESPONSALES'!H12<>"",OR(LEN('LID_CORRESPONSALES'!H12)>6,COUNTIF(CL_CASFIM,'LID_CORRESPONSALES'!H12)=0)),1,0) | I12: =IF(AND('LID_CORRESPONSALES'!I12<>"",COUNTIF(CL_CARACT_LIQ,'LID_CORRESPONSALES'!I12)=0),1,0) | J12: =IF(AND('LID_CORRESPONSALES'!J12<>"",NOT(ISNUMBER('LID_CORRESPONSALES'!J12))),1,0)
A13: =IF(AND('LID_CORRESPONSALES'!A13<>"",NOT(ISNUMBER('LID_CORRESPONSALES'!A13))),1,0) | B13: =IF(AND('LID_CORRESPONSALES'!B13<>"",LEN('LID_CORRESPONSALES'!B13)>5),1,0) | C13: =IF(AND('LID_CORRESPONSALES'!C13<>"",COUNTIF(CL_TIPO_VALOR,'LID_CORRESPONSALES'!C13)=0),1,0) | D13: =IF(AND('LID_CORRESPONSALES'!D13<>"",IF(ISNUMBER('LID_CORRESPONSALES'!D13),OR('LID_CORRESPONSALES'!D13<>ROUND('LID_CORRESPONSALES'!D13,0),LEN(TEXT(INT(ABS('LID_CORRESPONSALES'!D13)),"0"))>12),TRUE)),1,0) | E13: =IF(AND('LID_CORRESPONSALES'!E13<>"",OR(LEN('LID_CORRESPONSALES'!E13)>3,COUNTIF(CL_MONEDA,'LID_CORRESPONSALES'!E13)=0)),1,0) | F13: =IF(AND('LID_CORRESPONSALES'!F13<>"",COUNTIF(CL_ID_PAGOS_REAL,'LID_CORRESPONSALES'!F13)=0),1,0) | G13: =IF(AND('LID_CORRESPONSALES'!G13<>"",OR(LEN('LID_CORRESPONSALES'!G13)>6,COUNTIF(CL_CASFIM,'LID_CORRESPONSALES'!G13)=0)),1,0) | H13: =IF(AND('LID_CORRESPONSALES'!H13<>"",OR(LEN('LID_CORRESPONSALES'!H13)>6,COUNTIF(CL_CASFIM,'LID_CORRESPONSALES'!H13)=0)),1,0) | I13: =IF(AND('LID_CORRESPONSALES'!I13<>"",COUNTIF(CL_CARACT_LIQ,'LID_CORRESPONSALES'!I13)=0),1,0) | J13: =IF(AND('LID_CORRESPONSALES'!J13<>"",NOT(ISNUMBER('LID_CORRESPONSALES'!J13))),1,0)
... A201: =IF(AND('LID_CORRESPONSALES'!A201<>"",NOT(ISNUMBER('LID_CORRESPONSALES'!A201))),1,0) | B201: =IF(AND('LID_CORRESPONSALES'!B201<>"",LEN('LID_CORRESPONSALES'!B201)>5),1,0) | C201: =IF(AND('LID_CORRESPONSALES'!C201<>"",COUNTIF(CL_TIPO_VALOR,'LID_CORRESPONSALES'!C201)=0),1,0) | D201: =IF(AND('LID_CORRESPONSALES'!D201<>"",IF(ISNUMBER('LID_CORRESPONSALES'!D201),OR('LID_CORRESPONSALES'!D201<>ROUND('LID_CORRESPONSALES'!D201,0),LEN(TEXT(INT(ABS('LID_CORRESPONSALES'!D201)),"0"))>12),TRUE)),1,0) | E201: =IF(AND('LID_CORRESPONSALES'!E201<>"",OR(LEN('LID_CORRESPONSALES'!E201)>3,COUNTIF(CL_MONEDA,'LID_CORRESPONSALES'!E201)=0)),1,0) | F201: =IF(AND('LID_CORRESPONSALES'!F201<>"",COUNTIF(CL_ID_PAGOS_REAL,'LID_CORRESPONSALES'!F201)=0),1,0) | G201: =IF(AND('LID_CORRESPONSALES'!G201<>"",OR(LEN('LID_CORRESPONSALES'!G201)>6,COUNTIF(CL_CASFIM,'LID_CORRESPONSALES'!G201)=0)),1,0) | H201: =IF(AND('LID_CORRESPONSALES'!H201<>"",OR(LEN('LID_CORRESPONSALES'!H201)>6,COUNTIF(CL_CASFIM,'LID_CORRESPONSALES'!H201)=0)),1,0) | I201: =IF(AND('LID_CORRESPONSALES'!I201<>"",COUNTIF(CL_CARACT_LIQ,'LID_CORRESPONSALES'!I201)=0),1,0) | J201: =IF(AND('LID_CORRESPONSALES'!J201<>"",NOT(ISNUMBER('LID_CORRESPONSALES'!J201))),1,0)
